Workbook

Sheet HOME
B2: Montana Army National Guard Career Planning & Mentorship Tool
B3: Version 1.0 | DEMO DATA — Replace admin sheets with real MTARNG data before operational use
B5: MY PROFILE | D5: POSITION MATCHES | F5: COMMUTE ANALYSIS | H5: CAREER TIMELINE | J5: COUNSELING SHEET
B6: Start here. Enter your rank, MOS, unit, home city, and career goals. | D6: See all MTARNG positions scored against your profile. | F6: View drive time and distance from your home city to each position. | H6: See a suggested 10–20 year career pathway toward your goal. | J6: Print a 1-page counseling summary for your senior rater meeting.
B7: → Go to MY PROFILE | D7: → Go to POSITION MATCHES | F7: → Go to COMMUTE ANALYSIS | H7: → Go to CAREER TIMELINE | J7: → Go to COUNSELING SHEET
B9: ⚠ ADMIN SHEETS (red tabs): ADMIN - POSITIONS | ADMIN - CITY DISTANCES | ADMIN - PME AND SCHOOLS | ADMIN - MOS TRANSITIONS | ADMIN - PROMOTION TIMELINE
B11: HOW TO USE THIS TOOL
B12: STEP 1 | C12: Open MY PROFILE and fill in your information from top to bottom. Use the dropdown lists provided.
B13: STEP 2 | C13: Navigate to POSITION MATCHES to see every MTARNG position scored and ranked for your profile.
B14: STEP 3 | C14: Open COMMUTE ANALYSIS to understand the drive time and distance impact of each opportunity.
B15: STEP 4 | C15: Review CAREER TIMELINE for a suggested multi-year pathway toward your stated goal.
B16: STEP 5 | C16: Print COUNSELING SHEET and bring it to your senior rater, mentor, or retention NCO.
B17: FOR ADMINS | C17: Update the red-tab ADMIN sheets with real MTARNG data. Soldier-facing outputs update automatically.

Sheet MY PROFILE
B1: SOLDIER CAREER PROFILE | Montana Army National Guard
B2: Fill in the yellow cells. Use dropdown arrows where available. All Soldier-facing sheets update automatically from this page.
B4: SECTION 1 — SOLDIER IDENTITY & CURRENT STATUS
B5: Full Name (Last, First MI) | C5: Smith, John A. | F5: Last 4 SSN (optional) | G5: XXXX
B6: Current Rank / Grade | C6: E5 / SGT | D6: Career Category | E6: Enlisted | F6: Component / Status | G6: M-Day
B7: Primary MOS / AOC / Branch | C7: 92Y | D7: Secondary MOS (if any) | F7: Branch / Career Field (Officers) | G7: LG
B8: Current Unit Name | C8: 495th CSSC | F8: UIC (if known) | G8: W4MMMS
B9: Current Duty Title / Position | C9: Unit Supply Specialist | F9: City of Current Unit | G9: Missoula
B10: Home City (where you live) | C10: Missoula | D10: State (if not MT) | E10: MT | F10: Max Acceptable One-Way Commute | G10: 2 Hours
B11: Total Years of Service (ARNG + AD) | C11: 8 | D11: Years in Current Grade (TIG) | E11: 2 | F11: Time in Current Position (years) | G11: 1.5
B12: ETS / Expiration Term of Service | C12: 2027-08-01 | D12: Initial Entry Date (PEBD/DOR) | E12: 2018-06-01 | F12: Willing to Relocate for the Right Position? | G12: No
B14: SECTION 2 — PME & EDUCATION COMPLETED
B15: ENLISTED PME | D15: OFFICER PME | F15: WARRANT PME
B16: Basic Leader Course (BLC) | C16: No | D16: BOLC Complete | E16: No | F16: WOBC Complete | G16: No
B17: Advanced Leader Course (ALC) | C17: No | D17: Captain's Career Course (CCC) | E17: No | F17: WOAC Complete | G17: No
B18: Senior Leader Course (SLC) | C18: No | D18: ILE Complete | E18: No | F18: WOILE Complete | G18: No
B19: Sergeant Major Course (SMC) | C19: No | D19: Senior Service College (SSC) | E19: No | F19: WOSSE Complete | G19: No
B20: SSD1 Complete | C20: No
B21: SSD2 Complete | C21: No
B22: Highest Education Level | C22: Some College | D22: College Degree Field (if any) | E22: Business Administration | F22: Other Relevant Certifications | G22: APFT Master Fitness Trainer
B24: SECTION 3 — CAREER GOALS & ASPIRATIONS
B25: Target Rank / Goal Grade | C25: E7 / SFC | D25: Target Timeline (years from now) | E25: 4 | F25: Preferred Component After Next Move | G25: Either
B26: Primary Career Goal (select one) | C26: Promote to Next Grade | F26: Secondary Career Goal (optional) | G26: Pursue AGR Full-Time
B27: Desired Position Type (select one) | C27: Leadership | D27: Open to Command Position? | E27: Yes | F27: Want to switch MOS or Branch? | G27: No
B28: If switching — Target MOS / Branch | C28: N/A | D28: Warrant Officer Interest? | E28: No | F28: Long-term goal (10-20 yrs out) | G28: Senior NCO / Retention SGM
B30: 5-YEAR GOAL (describe in your own words):
B31: I want to promote to SFC within 4 years. I plan to complete SLC and move into a platoon sergeant or staff NCOIC role at a unit closer to Helena, ideally as an AGR position.
B34: 10-YEAR / LONG-RANGE GOAL:
B35: Long term, I'd like to either achieve MSG or pursue a warrant officer program if my career path allows. I want to finish my bachelor's degree and remain in Montana.
B39: SECTION 4 — ADDITIONAL CAREER INFORMATION
B40: Have you been to any command/KD position? | C40: No | D40: Currently promotable (P)? | E40: No | F40: On promotion list for current grade? | G40: No
B41: Previous Key Assignments (summarize) | C41: SPC - 92Y supply tech at 495th CSSC; SGT - acting supply NCOIC during annual training 2025
B42: Physical Fitness Status | C42: Passing | D42: Security Clearance Level | E42: Secret | F42: Deployment / GWOT Service | G42: 1 deployment (Afghanistan 2021)
B43: Awards / Distinction (brief summary) | C43: Army Achievement Medal x2, Army Commendation Medal, Expert Infantryman Badge
B44: Mentor Name (if identified) | D44: Mentor Rank / Role | F44: Senior Rater Name
B46: KEY PROFILE CELLS (used by CALC ENGINE) → Rank=C6 | Category=E6 | Status=G6 | MOS=C7 | HomeCity=C10 | MaxCommute=G10 | TargetRank=C25 | PrimaryGoal=C26 | PositionType=C27 | SwitchMOS=G27

Sheet POSITION MATCHES
B1: POSITION MATCHES | Scores update automatically when you change MY PROFILE
B2: =" Soldier: "&'MY PROFILE'!C6&" "&'MY PROFILE'!E6&" | MOS: "&'MY PROFILE'!C7&" | Home: "&'MY PROFILE'!C10&" | Target: "&'MY PROFILE'!C25&" | Goal: "&'MY PROFILE'!C26
C4: STRONG MATCH | E4: GOOD MATCH | G4: MODERATE / STRETCH | I4: POSSIBLE — GAPS | K4: NOT RECOMMENDED
B5: # | C5: Rank | D5: Unit | E5: City | F5: Duty Title | G5: Grade | H5: Cat | I5: MOS | J5: Position Type | K5: KD? | L5: Status | M5: Vacancy | N5: Grade Score | O5: MOS Score | P5: Commute Score | Q5: Goal Score | R5: Status Score | S5: TOTAL SCORE | T5: MATCH LABEL | U5: Commute (min)
B6: 1 | C6: ='CALC ENGINE'!B3 | D6: ='CALC ENGINE'!C3 | E6: ='CALC ENGINE'!D3 | F6: ='CALC ENGINE'!E3 | G6: ='CALC ENGINE'!F3 | H6: ='CALC ENGINE'!G3 | I6: ='CALC ENGINE'!H3 | J6: ='CALC ENGINE'!I3 | ... L6: ='CALC ENGINE'!K3 | M6: ='CALC ENGINE'!M3 | N6: ='CALC ENGINE'!N3 | O6: ='CALC ENGINE'!O3 | P6: ='CALC ENGINE'!P3 | Q6: ='CALC ENGINE'!Q3 | R6: ='CALC ENGINE'!R3 | S6: ='CALC ENGINE'!S3 | T6: ='CALC ENGINE'!T3
B7: 2 | C7: ='CALC ENGINE'!B4 | D7: ='CALC ENGINE'!C4 | E7: ='CALC ENGINE'!D4 | F7: ='CALC ENGINE'!E4 | G7: ='CALC ENGINE'!F4 | H7: ='CALC ENGINE'!G4 | I7: ='CALC ENGINE'!H4 | J7: ='CALC ENGINE'!I4 | ... L7: ='CALC ENGINE'!K4 | M7: ='CALC ENGINE'!M4 | N7: ='CALC ENGINE'!N4 | O7: ='CALC ENGINE'!O4 | P7: ='CALC ENGINE'!P4 | Q7: ='CALC ENGINE'!Q4 | R7: ='CALC ENGINE'!R4 | S7: ='CALC ENGINE'!S4 | T7: ='CALC ENGINE'!T4
B8: 3 | C8: ='CALC ENGINE'!B5 | D8: ='CALC ENGINE'!C5 | E8: ='CALC ENGINE'!D5 | F8: ='CALC ENGINE'!E5 | G8: ='CALC ENGINE'!F5 | H8: ='CALC ENGINE'!G5 | I8: ='CALC ENGINE'!H5 | J8: ='CALC ENGINE'!I5 | ... L8: ='CALC ENGINE'!K5 | M8: ='CALC ENGINE'!M5 | N8: ='CALC ENGINE'!N5 | O8: ='CALC ENGINE'!O5 | P8: ='CALC ENGINE'!P5 | Q8: ='CALC ENGINE'!Q5 | R8: ='CALC ENGINE'!R5 | S8: ='CALC ENGINE'!S5 | T8: ='CALC ENGINE'!T5
B9: 4 | C9: ='CALC ENGINE'!B6 | D9: ='CALC ENGINE'!C6 | E9: ='CALC ENGINE'!D6 | F9: ='CALC ENGINE'!E6 | G9: ='CALC ENGINE'!F6 | H9: ='CALC ENGINE'!G6 | I9: ='CALC ENGINE'!H6 | J9: ='CALC ENGINE'!I6 | ... L9: ='CALC ENGINE'!K6 | M9: ='CALC ENGINE'!M6 | N9: ='CALC ENGINE'!N6 | O9: ='CALC ENGINE'!O6 | P9: ='CALC ENGINE'!P6 | Q9: ='CALC ENGINE'!Q6 | R9: ='CALC ENGINE'!R6 | S9: ='CALC ENGINE'!S6 | T9: ='CALC ENGINE'!T6
B10: 5 | C10: ='CALC ENGINE'!B7 | D10: ='CALC ENGINE'!C7 | E10: ='CALC ENGINE'!D7 | F10: ='CALC ENGINE'!E7 | G10: ='CALC ENGINE'!F7 | H10: ='CALC ENGINE'!G7 | I10: ='CALC ENGINE'!H7 | J10: ='CALC ENGINE'!I7 | ... L10: ='CALC ENGINE'!K7 | M10: ='CALC ENGINE'!M7 | N10: ='CALC ENGINE'!N7 | O10: ='CALC ENGINE'!O7 | P10: ='CALC ENGINE'!P7 | Q10: ='CALC ENGINE'!Q7 | R10: ='CALC ENGINE'!R7 | S10: ='CALC ENGINE'!S7 | T10: ='CALC ENGINE'!T7
B11: 6 | C11: ='CALC ENGINE'!B8 | D11: ='CALC ENGINE'!C8 | E11: ='CALC ENGINE'!D8 | F11: ='CALC ENGINE'!E8 | G11: ='CALC ENGINE'!F8 | H11: ='CALC ENGINE'!G8 | I11: ='CALC ENGINE'!H8 | J11: ='CALC ENGINE'!I8 | ... L11: ='CALC ENGINE'!K8 | M11: ='CALC ENGINE'!M8 | N11: ='CALC ENGINE'!N8 | O11: ='CALC ENGINE'!O8 | P11: ='CALC ENGINE'!P8 | Q11: ='CALC ENGINE'!Q8 | R11: ='CALC ENGINE'!R8 | S11: ='CALC ENGINE'!S8 | T11: ='CALC ENGINE'!T8
B12: 7 | C12: ='CALC ENGINE'!B9 | D12: ='CALC ENGINE'!C9 | E12: ='CALC ENGINE'!D9 | F12: ='CALC ENGINE'!E9 | G12: ='CALC ENGINE'!F9 | H12: ='CALC ENGINE'!G9 | I12: ='CALC ENGINE'!H9 | J12: ='CALC ENGINE'!I9 | ... L12: ='CALC ENGINE'!K9 | M12: ='CALC ENGINE'!M9 | N12: ='CALC ENGINE'!N9 | O12: ='CALC ENGINE'!O9 | P12: ='CALC ENGINE'!P9 | Q12: ='CALC ENGINE'!Q9 | R12: ='CALC ENGINE'!R9 | S12: ='CALC ENGINE'!S9 | T12: ='CALC ENGINE'!T9
B13: 8 | C13: ='CALC ENGINE'!B10 | D13: ='CALC ENGINE'!C10 | E13: ='CALC ENGINE'!D10 | F13: ='CALC ENGINE'!E10 | G13: ='CALC ENGINE'!F10 | H13: ='CALC ENGINE'!G10 | I13: ='CALC ENGINE'!H10 | J13: ='CALC ENGINE'!I10 | ... L13: ='CALC ENGINE'!K10 | M13: ='CALC ENGINE'!M10 | N13: ='CALC ENGINE'!N10 | O13: ='CALC ENGINE'!O10 | P13: ='CALC ENGINE'!P10 | Q13: ='CALC ENGINE'!Q10 | R13: ='CALC ENGINE'!R10 | S13: ='CALC ENGINE'!S10 | T13: ='CALC ENGINE'!T10
B14: 9 | C14: ='CALC ENGINE'!B11 | D14: ='CALC ENGINE'!C11 | E14: ='CALC ENGINE'!D11 | F14: ='CALC ENGINE'!E11 | G14: ='CALC ENGINE'!F11 | H14: ='CALC ENGINE'!G11 | I14: ='CALC ENGINE'!H11 | J14: ='CALC ENGINE'!I11 | ... L14: ='CALC ENGINE'!K11 | M14: ='CALC ENGINE'!M11 | N14: ='CALC ENGINE'!N11 | O14: ='CALC ENGINE'!O11 | P14: ='CALC ENGINE'!P11 | Q14: ='CALC ENGINE'!Q11 | R14: ='CALC ENGINE'!R11 | S14: ='CALC ENGINE'!S11 | T14: ='CALC ENGINE'!T11
B15: 10 | C15: ='CALC ENGINE'!B12 | D15: ='CALC ENGINE'!C12 | E15: ='CALC ENGINE'!D12 | F15: ='CALC ENGINE'!E12 | G15: ='CALC ENGINE'!F12 | H15: ='CALC ENGINE'!G12 | I15: ='CALC ENGINE'!H12 | J15: ='CALC ENGINE'!I12 | ... L15: ='CALC ENGINE'!K12 | M15: ='CALC ENGINE'!M12 | N15: ='CALC ENGINE'!N12 | O15: ='CALC ENGINE'!O12 | P15: ='CALC ENGINE'!P12 | Q15: ='CALC ENGINE'!Q12 | R15: ='CALC ENGINE'!R12 | S15: ='CALC ENGINE'!S12 | T15: ='CALC ENGINE'!T12
B16: 11 | C16: ='CALC ENGINE'!B13 | D16: ='CALC ENGINE'!C13 | E16: ='CALC ENGINE'!D13 | F16: ='CALC ENGINE'!E13 | G16: ='CALC ENGINE'!F13 | H16: ='CALC ENGINE'!G13 | I16: ='CALC ENGINE'!H13 | J16: ='CALC ENGINE'!I13 | ... L16: ='CALC ENGINE'!K13 | M16: ='CALC ENGINE'!M13 | N16: ='CALC ENGINE'!N13 | O16: ='CALC ENGINE'!O13 | P16: ='CALC ENGINE'!P13 | Q16: ='CALC ENGINE'!Q13 | R16: ='CALC ENGINE'!R13 | S16: ='CALC ENGINE'!S13 | T16: ='CALC ENGINE'!T13
B17: 12 | C17: ='CALC ENGINE'!B14 | D17: ='CALC ENGINE'!C14 | E17: ='CALC ENGINE'!D14 | F17: ='CALC ENGINE'!E14 | G17: ='CALC ENGINE'!F14 | H17: ='CALC ENGINE'!G14 | I17: ='CALC ENGINE'!H14 | J17: ='CALC ENGINE'!I14 | ... L17: ='CALC ENGINE'!K14 | M17: ='CALC ENGINE'!M14 | N17: ='CALC ENGINE'!N14 | O17: ='CALC ENGINE'!O14 | P17: ='CALC ENGINE'!P14 | Q17: ='CALC ENGINE'!Q14 | R17: ='CALC ENGINE'!R14 | S17: ='CALC ENGINE'!S14 | T17: ='CALC ENGINE'!T14
... B85: 80 | C85: ='CALC ENGINE'!B82 | D85: ='CALC ENGINE'!C82 | E85: ='CALC ENGINE'!D82 | F85: ='CALC ENGINE'!E82 | G85: ='CALC ENGINE'!F82 | H85: ='CALC ENGINE'!G82 | I85: ='CALC ENGINE'!H82 | J85: ='CALC ENGINE'!I82 | ... L85: ='CALC ENGINE'!K82 | M85: ='CALC ENGINE'!M82 | N85: ='CALC ENGINE'!N82 | O85: ='CALC ENGINE'!O82 | P85: ='CALC ENGINE'!P82 | Q85: ='CALC ENGINE'!Q82 | R85: ='CALC ENGINE'!R82 | S85: ='CALC ENGINE'!S82 | T85: ='CALC ENGINE'!T82

Sheet COMMUTE ANALYSIS
B1: COMMUTE ANALYSIS | Drive time and distance impact for each matched position
B2: ="Home City: "&'MY PROFILE'!C10&" | Max Commute: "&'MY PROFILE'!G10&" | Positions showing: All 80 — filter by MATCH LABEL or VACANCY"
C4: SHORT (≤30 min) | E4: MEDIUM (31–90 min) | G4: LONG (91–180 min) | I4: VERY LONG (>180 min) | K4: SAME CITY
B5: # | C5: Unit | D5: Position City | E5: Duty Title | F5: Grade | G5: One-Way (min) | H5: One-Way (miles approx) | I5: Round Trip (min) | J5: Drill WE (4 legs, hrs) | K5: Within Max? | L5: Commute Category | M5: Match Label
B6: 1 | C6: ='CALC ENGINE'!B3 | D6: ='CALC ENGINE'!C3 | E6: ='CALC ENGINE'!D3 | F6: ='CALC ENGINE'!E3 | G6: ='CALC ENGINE'!T3 | H6: =IFERROR(SUMPRODUCT(($A$201:$A$293='MY PROFILE'!C10)*($B$201:$B$293=C6)*($C$201:$C$293)),0) | I6: =IF(G6=999,"",G6*2) | J6: =IF(G6=999,"",ROUND(G6*4/60,1)&" hrs") | K6: =IF(G6=999,"Unknown",IF('MY PROFILE'!G10="No Limit","Yes",IF('MY PROFILE'!G10="30 Minutes",IF(G6<=30,"Yes","No"),IF('MY PROFILE'!G10="1 Hour",IF(G6<=60,"Yes","No"),IF('MY PROFILE'!G10="1.5 Hours",IF(G6<=90,"Yes","No"),IF('MY PROFILE'!G10="2 Hours",IF(G6<=120,"Yes","No"),IF('MY PROFILE'!G10="3 Hours",IF(G6<=180,"Yes","No"),"No"))))))) | L6: =IF(G6=0,"Same City",IF(G6<=30,"Short",IF(G6<=90,"Medium",IF(G6<=180,"Long","Very Long")))) | M6: ='CALC ENGINE'!S3
B7: 2 | C7: ='CALC ENGINE'!B4 | D7: ='CALC ENGINE'!C4 | E7: ='CALC ENGINE'!D4 | F7: ='CALC ENGINE'!E4 | G7: ='CALC ENGINE'!T4 | H7: =IFERROR(SUMPRODUCT(($A$201:$A$293='MY PROFILE'!C10)*($B$201:$B$293=C7)*($C$201:$C$293)),0) | I7: =IF(G7=999,"",G7*2) | J7: =IF(G7=999,"",ROUND(G7*4/60,1)&" hrs") | K7: =IF(G7=999,"Unknown",IF('MY PROFILE'!G10="No Limit","Yes",IF('MY PROFILE'!G10="30 Minutes",IF(G7<=30,"Yes","No"),IF('MY PROFILE'!G10="1 Hour",IF(G7<=60,"Yes","No"),IF('MY PROFILE'!G10="1.5 Hours",IF(G7<=90,"Yes","No"),IF('MY PROFILE'!G10="2 Hours",IF(G7<=120,"Yes","No"),IF('MY PROFILE'!G10="3 Hours",IF(G7<=180,"Yes","No"),"No"))))))) | L7: =IF(G7=0,"Same City",IF(G7<=30,"Short",IF(G7<=90,"Medium",IF(G7<=180,"Long","Very Long")))) | M7: ='CALC ENGINE'!S4
B8: 3 | C8: ='CALC ENGINE'!B5 | D8: ='CALC ENGINE'!C5 | E8: ='CALC ENGINE'!D5 | F8: ='CALC ENGINE'!E5 | G8: ='CALC ENGINE'!T5 | H8: =IFERROR(SUMPRODUCT(($A$201:$A$293='MY PROFILE'!C10)*($B$201:$B$293=C8)*($C$201:$C$293)),0) | I8: =IF(G8=999,"",G8*2) | J8: =IF(G8=999,"",ROUND(G8*4/60,1)&" hrs") | K8: =IF(G8=999,"Unknown",IF('MY PROFILE'!G10="No Limit","Yes",IF('MY PROFILE'!G10="30 Minutes",IF(G8<=30,"Yes","No"),IF('MY PROFILE'!G10="1 Hour",IF(G8<=60,"Yes","No"),IF('MY PROFILE'!G10="1.5 Hours",IF(G8<=90,"Yes","No"),IF('MY PROFILE'!G10="2 Hours",IF(G8<=120,"Yes","No"),IF('MY PROFILE'!G10="3 Hours",IF(G8<=180,"Yes","No"),"No"))))))) | L8: =IF(G8=0,"Same City",IF(G8<=30,"Short",IF(G8<=90,"Medium",IF(G8<=180,"Long","Very Long")))) | M8: ='CALC ENGINE'!S5
B9: 4 | C9: ='CALC ENGINE'!B6 | D9: ='CALC ENGINE'!C6 | E9: ='CALC ENGINE'!D6 | F9: ='CALC ENGINE'!E6 | G9: ='CALC ENGINE'!T6 | H9: =IFERROR(SUMPRODUCT(($A$201:$A$293='MY PROFILE'!C10)*($B$201:$B$293=C9)*($C$201:$C$293)),0) | I9: =IF(G9=999,"",G9*2) | J9: =IF(G9=999,"",ROUND(G9*4/60,1)&" hrs") | K9: =IF(G9=999,"Unknown",IF('MY PROFILE'!G10="No Limit","Yes",IF('MY PROFILE'!G10="30 Minutes",IF(G9<=30,"Yes","No"),IF('MY PROFILE'!G10="1 Hour",IF(G9<=60,"Yes","No"),IF('MY PROFILE'!G10="1.5 Hours",IF(G9<=90,"Yes","No"),IF('MY PROFILE'!G10="2 Hours",IF(G9<=120,"Yes","No"),IF('MY PROFILE'!G10="3 Hours",IF(G9<=180,"Yes","No"),"No"))))))) | L9: =IF(G9=0,"Same City",IF(G9<=30,"Short",IF(G9<=90,"Medium",IF(G9<=180,"Long","Very Long")))) | M9: ='CALC ENGINE'!S6
B10: 5 | C10: ='CALC ENGINE'!B7 | D10: ='CALC ENGINE'!C7 | E10: ='CALC ENGINE'!D7 | F10: ='CALC ENGINE'!E7 | G10: ='CALC ENGINE'!T7 | H10: =IFERROR(SUMPRODUCT(($A$201:$A$293='MY PROFILE'!C10)*($B$201:$B$293=C10)*($C$201:$C$293)),0) | I10: =IF(G10=999,"",G10*2) | J10: =IF(G10=999,"",ROUND(G10*4/60,1)&" hrs") | K10: =IF(G10=999,"Unknown",IF('MY PROFILE'!G10="No Limit","Yes",IF('MY PROFILE'!G10="30 Minutes",IF(G10<=30,"Yes","No"),IF('MY PROFILE'!G10="1 Hour",IF(G10<=60,"Yes","No"),IF('MY PROFILE'!G10="1.5 Hours",IF(G10<=90,"Yes","No"),IF('MY PROFILE'!G10="2 Hours",IF(G10<=120,"Yes","No"),IF('MY PROFILE'!G10="3 Hours",IF(G10<=180,"Yes","No"),"No"))))))) | L10: =IF(G10=0,"Same City",IF(G10<=30,"Short",IF(G10<=90,"Medium",IF(G10<=180,"Long","Very Long")))) | M10: ='CALC ENGINE'!S7
B11: 6 | C11: ='CALC ENGINE'!B8 | D11: ='CALC ENGINE'!C8 | E11: ='CALC ENGINE'!D8 | F11: ='CALC ENGINE'!E8 | G11: ='CALC ENGINE'!T8 | H11: =IFERROR(SUMPRODUCT(($A$201:$A$293='MY PROFILE'!C10)*($B$201:$B$293=C11)*($C$201:$C$293)),0) | I11: =IF(G11=999,"",G11*2) | J11: =IF(G11=999,"",ROUND(G11*4/60,1)&" hrs") | K11: =IF(G11=999,"Unknown",IF('MY PROFILE'!G10="No Limit","Yes",IF('MY PROFILE'!G10="30 Minutes",IF(G11<=30,"Yes","No"),IF('MY PROFILE'!G10="1 Hour",IF(G11<=60,"Yes","No"),IF('MY PROFILE'!G10="1.5 Hours",IF(G11<=90,"Yes","No"),IF('MY PROFILE'!G10="2 Hours",IF(G11<=120,"Yes","No"),IF('MY PROFILE'!G10="3 Hours",IF(G11<=180,"Yes","No"),"No"))))))) | L11: =IF(G11=0,"Same City",IF(G11<=30,"Short",IF(G11<=90,"Medium",IF(G11<=180,"Long","Very Long")))) | M11: ='CALC ENGINE'!S8
B12: 7 | C12: ='CALC ENGINE'!B9 | D12: ='CALC ENGINE'!C9 | E12: ='CALC ENGINE'!D9 | F12: ='CALC ENGINE'!E9 | G12: ='CALC ENGINE'!T9 | H12: =IFERROR(SUMPRODUCT(($A$201:$A$293='MY PROFILE'!C10)*($B$201:$B$293=C12)*($C$201:$C$293)),0) | I12: =IF(G12=999,"",G12*2) | J12: =IF(G12=999,"",ROUND(G12*4/60,1)&" hrs") | K12: =IF(G12=999,"Unknown",IF('MY PROFILE'!G10="No Limit","Yes",IF('MY PROFILE'!G10="30 Minutes",IF(G12<=30,"Yes","No"),IF('MY PROFILE'!G10="1 Hour",IF(G12<=60,"Yes","No"),IF('MY PROFILE'!G10="1.5 Hours",IF(G12<=90,"Yes","No"),IF('MY PROFILE'!G10="2 Hours",IF(G12<=120,"Yes","No"),IF('MY PROFILE'!G10="3 Hours",IF(G12<=180,"Yes","No"),"No"))))))) | L12: =IF(G12=0,"Same City",IF(G12<=30,"Short",IF(G12<=90,"Medium",IF(G12<=180,"Long","Very Long")))) | M12: ='CALC ENGINE'!S9
B13: 8 | C13: ='CALC ENGINE'!B10 | D13: ='CALC ENGINE'!C10 | E13: ='CALC ENGINE'!D10 | F13: ='CALC ENGINE'!E10 | G13: ='CALC ENGINE'!T10 | H13: =IFERROR(SUMPRODUCT(($A$201:$A$293='MY PROFILE'!C10)*($B$201:$B$293=C13)*($C$201:$C$293)),0) | I13: =IF(G13=999,"",G13*2) | J13: =IF(G13=999,"",ROUND(G13*4/60,1)&" hrs") | K13: =IF(G13=999,"Unknown",IF('MY PROFILE'!G10="No Limit","Yes",IF('MY PROFILE'!G10="30 Minutes",IF(G13<=30,"Yes","No"),IF('MY PROFILE'!G10="1 Hour",IF(G13<=60,"Yes","No"),IF('MY PROFILE'!G10="1.5 Hours",IF(G13<=90,"Yes","No"),IF('MY PROFILE'!G10="2 Hours",IF(G13<=120,"Yes","No"),IF('MY PROFILE'!G10="3 Hours",IF(G13<=180,"Yes","No"),"No"))))))) | L13: =IF(G13=0,"Same City",IF(G13<=30,"Short",IF(G13<=90,"Medium",IF(G13<=180,"Long","Very Long")))) | M13: ='CALC ENGINE'!S10
B14: 9 | C14: ='CALC ENGINE'!B11 | D14: ='CALC ENGINE'!C11 | E14: ='CALC ENGINE'!D11 | F14: ='CALC ENGINE'!E11 | G14: ='CALC ENGINE'!T11 | H14: =IFERROR(SUMPRODUCT(($A$201:$A$293='MY PROFILE'!C10)*($B$201:$B$293=C14)*($C$201:$C$293)),0) | I14: =IF(G14=999,"",G14*2) | J14: =IF(G14=999,"",ROUND(G14*4/60,1)&" hrs") | K14: =IF(G14=999,"Unknown",IF('MY PROFILE'!G10="No Limit","Yes",IF('MY PROFILE'!G10="30 Minutes",IF(G14<=30,"Yes","No"),IF('MY PROFILE'!G10="1 Hour",IF(G14<=60,"Yes","No"),IF('MY PROFILE'!G10="1.5 Hours",IF(G14<=90,"Yes","No"),IF('MY PROFILE'!G10="2 Hours",IF(G14<=120,"Yes","No"),IF('MY PROFILE'!G10="3 Hours",IF(G14<=180,"Yes","No"),"No"))))))) | L14: =IF(G14=0,"Same City",IF(G14<=30,"Short",IF(G14<=90,"Medium",IF(G14<=180,"Long","Very Long")))) | M14: ='CALC ENGINE'!S11
B15: 10 | C15: ='CALC ENGINE'!B12 | D15: ='CALC ENGINE'!C12 | E15: ='CALC ENGINE'!D12 | F15: ='CALC ENGINE'!E12 | G15: ='CALC ENGINE'!T12 | H15: =IFERROR(SUMPRODUCT(($A$201:$A$293='MY PROFILE'!C10)*($B$201:$B$293=C15)*($C$201:$C$293)),0) | I15: =IF(G15=999,"",G15*2) | J15: =IF(G15=999,"",ROUND(G15*4/60,1)&" hrs") | K15: =IF(G15=999,"Unknown",IF('MY PROFILE'!G10="No Limit","Yes",IF('MY PROFILE'!G10="30 Minutes",IF(G15<=30,"Yes","No"),IF('MY PROFILE'!G10="1 Hour",IF(G15<=60,"Yes","No"),IF('MY PROFILE'!G10="1.5 Hours",IF(G15<=90,"Yes","No"),IF('MY PROFILE'!G10="2 Hours",IF(G15<=120,"Yes","No"),IF('MY PROFILE'!G10="3 Hours",IF(G15<=180,"Yes","No"),"No"))))))) | L15: =IF(G15=0,"Same City",IF(G15<=30,"Short",IF(G15<=90,"Medium",IF(G15<=180,"Long","Very Long")))) | M15: ='CALC ENGINE'!S12
B16: 11 | C16: ='CALC ENGINE'!B13 | D16: ='CALC ENGINE'!C13 | E16: ='CALC ENGINE'!D13 | F16: ='CALC ENGINE'!E13 | G16: ='CALC ENGINE'!T13 | H16: =IFERROR(SUMPRODUCT(($A$201:$A$293='MY PROFILE'!C10)*($B$201:$B$293=C16)*($C$201:$C$293)),0) | I16: =IF(G16=999,"",G16*2) | J16: =IF(G16=999,"",ROUND(G16*4/60,1)&" hrs") | K16: =IF(G16=999,"Unknown",IF('MY PROFILE'!G10="No Limit","Yes",IF('MY PROFILE'!G10="30 Minutes",IF(G16<=30,"Yes","No"),IF('MY PROFILE'!G10="1 Hour",IF(G16<=60,"Yes","No"),IF('MY PROFILE'!G10="1.5 Hours",IF(G16<=90,"Yes","No"),IF('MY PROFILE'!G10="2 Hours",IF(G16<=120,"Yes","No"),IF('MY PROFILE'!G10="3 Hours",IF(G16<=180,"Yes","No"),"No"))))))) | L16: =IF(G16=0,"Same City",IF(G16<=30,"Short",IF(G16<=90,"Medium",IF(G16<=180,"Long","Very Long")))) | M16: ='CALC ENGINE'!S13
B17: 12 | C17: ='CALC ENGINE'!B14 | D17: ='CALC ENGINE'!C14 | E17: ='CALC ENGINE'!D14 | F17: ='CALC ENGINE'!E14 | G17: ='CALC ENGINE'!T14 | H17: =IFERROR(SUMPRODUCT(($A$201:$A$293='MY PROFILE'!C10)*($B$201:$B$293=C17)*($C$201:$C$293)),0) | I17: =IF(G17=999,"",G17*2) | J17: =IF(G17=999,"",ROUND(G17*4/60,1)&" hrs") | K17: =IF(G17=999,"Unknown",IF('MY PROFILE'!G10="No Limit","Yes",IF('MY PROFILE'!G10="30 Minutes",IF(G17<=30,"Yes","No"),IF('MY PROFILE'!G10="1 Hour",IF(G17<=60,"Yes","No"),IF('MY PROFILE'!G10="1.5 Hours",IF(G17<=90,"Yes","No"),IF('MY PROFILE'!G10="2 Hours",IF(G17<=120,"Yes","No"),IF('MY PROFILE'!G10="3 Hours",IF(G17<=180,"Yes","No"),"No"))))))) | L17: =IF(G17=0,"Same City",IF(G17<=30,"Short",IF(G17<=90,"Medium",IF(G17<=180,"Long","Very Long")))) | M17: ='CALC ENGINE'!S14
B18: 13 | C18: ='CALC ENGINE'!B15 | D18: ='CALC ENGINE'!C15 | E18: ='CALC ENGINE'!D15 | F18: ='CALC ENGINE'!E15 | G18: ='CALC ENGINE'!T15 | H18: =IFERROR(SUMPRODUCT(($A$201:$A$293='MY PROFILE'!C10)*($B$201:$B$293=C18)*($C$201:$C$293)),0) | I18: =IF(G18=999,"",G18*2) | J18: =IF(G18=999,"",ROUND(G18*4/60,1)&" hrs") | K18: =IF(G18=999,"Unknown",IF('MY PROFILE'!G10="No Limit","Yes",IF('MY PROFILE'!G10="30 Minutes",IF(G18<=30,"Yes","No"),IF('MY PROFILE'!G10="1 Hour",IF(G18<=60,"Yes","No"),IF('MY PROFILE'!G10="1.5 Hours",IF(G18<=90,"Yes","No"),IF('MY PROFILE'!G10="2 Hours",IF(G18<=120,"Yes","No"),IF('MY PROFILE'!G10="3 Hours",IF(G18<=180,"Yes","No"),"No"))))))) | L18: =IF(G18=0,"Same City",IF(G18<=30,"Short",IF(G18<=90,"Medium",IF(G18<=180,"Long","Very Long")))) | M18: ='CALC ENGINE'!S15
B19: 14 | C19: ='CALC ENGINE'!B16 | D19: ='CALC ENGINE'!C16 | E19: ='CALC ENGINE'!D16 | F19: ='CALC ENGINE'!E16 | G19: ='CALC ENGINE'!T16 | H19: =IFERROR(SUMPRODUCT(($A$201:$A$293='MY PROFILE'!C10)*($B$201:$B$293=C19)*($C$201:$C$293)),0) | I19: =IF(G19=999,"",G19*2) | J19: =IF(G19=999,"",ROUND(G19*4/60,1)&" hrs") | K19: =IF(G19=999,"Unknown",IF('MY PROFILE'!G10="No Limit","Yes",IF('MY PROFILE'!G10="30 Minutes",IF(G19<=30,"Yes","No"),IF('MY PROFILE'!G10="1 Hour",IF(G19<=60,"Yes","No"),IF('MY PROFILE'!G10="1.5 Hours",IF(G19<=90,"Yes","No"),IF('MY PROFILE'!G10="2 Hours",IF(G19<=120,"Yes","No"),IF('MY PROFILE'!G10="3 Hours",IF(G19<=180,"Yes","No"),"No"))))))) | L19: =IF(G19=0,"Same City",IF(G19<=30,"Short",IF(G19<=90,"Medium",IF(G19<=180,"Long","Very Long")))) | M19: ='CALC ENGINE'!S16
B20: 15 | C20: ='CALC ENGINE'!B17 | D20: ='CALC ENGINE'!C17 | E20: ='CALC ENGINE'!D17 | F20: ='CALC ENGINE'!E17 | G20: ='CALC ENGINE'!T17 | H20: =IFERROR(SUMPRODUCT(($A$201:$A$293='MY PROFILE'!C10)*($B$201:$B$293=C20)*($C$201:$C$293)),0) | I20: =IF(G20=999,"",G20*2) | J20: =IF(G20=999,"",ROUND(G20*4/60,1)&" hrs") | K20: =IF(G20=999,"Unknown",IF('MY PROFILE'!G10="No Limit","Yes",IF('MY PROFILE'!G10="30 Minutes",IF(G20<=30,"Yes","No"),IF('MY PROFILE'!G10="1 Hour",IF(G20<=60,"Yes","No"),IF('MY PROFILE'!G10="1.5 Hours",IF(G20<=90,"Yes","No"),IF('MY PROFILE'!G10="2 Hours",IF(G20<=120,"Yes","No"),IF('MY PROFILE'!G10="3 Hours",IF(G20<=180,"Yes","No"),"No"))))))) | L20: =IF(G20=0,"Same City",IF(G20<=30,"Short",IF(G20<=90,"Medium",IF(G20<=180,"Long","Very Long")))) | M20: ='CALC ENGINE'!S17
B21: 16 | C21: ='CALC ENGINE'!B18 | D21: ='CALC ENGINE'!C18 | E21: ='CALC ENGINE'!D18 | F21: ='CALC ENGINE'!E18 | G21: ='CALC ENGINE'!T18 | H21: =IFERROR(SUMPRODUCT(($A$201:$A$293='MY PROFILE'!C10)*($B$201:$B$293=C21)*($C$201:$C$293)),0) | I21: =IF(G21=999,"",G21*2) | J21: =IF(G21=999,"",ROUND(G21*4/60,1)&" hrs") | K21: =IF(G21=999,"Unknown",IF('MY PROFILE'!G10="No Limit","Yes",IF('MY PROFILE'!G10="30 Minutes",IF(G21<=30,"Yes","No"),IF('MY PROFILE'!G10="1 Hour",IF(G21<=60,"Yes","No"),IF('MY PROFILE'!G10="1.5 Hours",IF(G21<=90,"Yes","No"),IF('MY PROFILE'!G10="2 Hours",IF(G21<=120,"Yes","No"),IF('MY PROFILE'!G10="3 Hours",IF(G21<=180,"Yes","No"),"No"))))))) | L21: =IF(G21=0,"Same City",IF(G21<=30,"Short",IF(G21<=90,"Medium",IF(G21<=180,"Long","Very Long")))) | M21: ='CALC ENGINE'!S18
B22: 17 | C22: ='CALC ENGINE'!B19 | D22: ='CALC ENGINE'!C19 | E22: ='CALC ENGINE'!D19 | F22: ='CALC ENGINE'!E19 | G22: ='CALC ENGINE'!T19 | H22: =IFERROR(SUMPRODUCT(($A$201:$A$293='MY PROFILE'!C10)*($B$201:$B$293=C22)*($C$201:$C$293)),0) | I22: =IF(G22=999,"",G22*2) | J22: =IF(G22=999,"",ROUND(G22*4/60,1)&" hrs") | K22: =IF(G22=999,"Unknown",IF('MY PROFILE'!G10="No Limit","Yes",IF('MY PROFILE'!G10="30 Minutes",IF(G22<=30,"Yes","No"),IF('MY PROFILE'!G10="1 Hour",IF(G22<=60,"Yes","No"),IF('MY PROFILE'!G10="1.5 Hours",IF(G22<=90,"Yes","No"),IF('MY PROFILE'!G10="2 Hours",IF(G22<=120,"Yes","No"),IF('MY PROFILE'!G10="3 Hours",IF(G22<=180,"Yes","No"),"No"))))))) | L22: =IF(G22=0,"Same City",IF(G22<=30,"Short",IF(G22<=90,"Medium",IF(G22<=180,"Long","Very Long")))) | M22: ='CALC ENGINE'!S19
B23: 18 | C23: ='CALC ENGINE'!B20 | D23: ='CALC ENGINE'!C20 | E23: ='CALC ENGINE'!D20 | F23: ='CALC ENGINE'!E20 | G23: ='CALC ENGINE'!T20 | H23: =IFERROR(SUMPRODUCT(($A$201:$A$293='MY PROFILE'!C10)*($B$201:$B$293=C23)*($C$201:$C$293)),0) | I23: =IF(G23=999,"",G23*2) | J23: =IF(G23=999,"",ROUND(G23*4/60,1)&" hrs") | K23: =IF(G23=999,"Unknown",IF('MY PROFILE'!G10="No Limit","Yes",IF('MY PROFILE'!G10="30 Minutes",IF(G23<=30,"Yes","No"),IF('MY PROFILE'!G10="1 Hour",IF(G23<=60,"Yes","No"),IF('MY PROFILE'!G10="1.5 Hours",IF(G23<=90,"Yes","No"),IF('MY PROFILE'!G10="2 Hours",IF(G23<=120,"Yes","No"),IF('MY PROFILE'!G10="3 Hours",IF(G23<=180,"Yes","No"),"No"))))))) | L23: =IF(G23=0,"Same City",IF(G23<=30,"Short",IF(G23<=90,"Medium",IF(G23<=180,"Long","Very Long")))) | M23: ='CALC ENGINE'!S20
B24: 19 | C24: ='CALC ENGINE'!B21 | D24: ='CALC ENGINE'!C21 | E24: ='CALC ENGINE'!D21 | F24: ='CALC ENGINE'!E21 | G24: ='CALC ENGINE'!T21 | H24: =IFERROR(SUMPRODUCT(($A$201:$A$293='MY PROFILE'!C10)*($B$201:$B$293=C24)*($C$201:$C$293)),0) | I24: =IF(G24=999,"",G24*2) | J24: =IF(G24=999,"",ROUND(G24*4/60,1)&" hrs") | K24: =IF(G24=999,"Unknown",IF('MY PROFILE'!G10="No Limit","Yes",IF('MY PROFILE'!G10="30 Minutes",IF(G24<=30,"Yes","No"),IF('MY PROFILE'!G10="1 Hour",IF(G24<=60,"Yes","No"),IF('MY PROFILE'!G10="1.5 Hours",IF(G24<=90,"Yes","No"),IF('MY PROFILE'!G10="2 Hours",IF(G24<=120,"Yes","No"),IF('MY PROFILE'!G10="3 Hours",IF(G24<=180,"Yes","No"),"No"))))))) | L24: =IF(G24=0,"Same City",IF(G24<=30,"Short",IF(G24<=90,"Medium",IF(G24<=180,"Long","Very Long")))) | M24: ='CALC ENGINE'!S21
B25: 20 | C25: ='CALC ENGINE'!B22 | D25: ='CALC ENGINE'!C22 | E25: ='CALC ENGINE'!D22 | F25: ='CALC ENGINE'!E22 | G25: ='CALC ENGINE'!T22 | H25: =IFERROR(SUMPRODUCT(($A$201:$A$293='MY PROFILE'!C10)*($B$201:$B$293=C25)*($C$201:$C$293)),0) | I25: =IF(G25=999,"",G25*2) | J25: =IF(G25=999,"",ROUND(G25*4/60,1)&" hrs") | K25: =IF(G25=999,"Unknown",IF('MY PROFILE'!G10="No Limit","Yes",IF('MY PROFILE'!G10="30 Minutes",IF(G25<=30,"Yes","No"),IF('MY PROFILE'!G10="1 Hour",IF(G25<=60,"Yes","No"),IF('MY PROFILE'!G10="1.5 Hours",IF(G25<=90,"Yes","No"),IF('MY PROFILE'!G10="2 Hours",IF(G25<=120,"Yes","No"),IF('MY PROFILE'!G10="3 Hours",IF(G25<=180,"Yes","No"),"No"))))))) | L25: =IF(G25=0,"Same City",IF(G25<=30,"Short",IF(G25<=90,"Medium",IF(G25<=180,"Long","Very Long")))) | M25: ='CALC ENGINE'!S22
B26: 21 | C26: ='CALC ENGINE'!B23 | D26: ='CALC ENGINE'!C23 | E26: ='CALC ENGINE'!D23 | F26: ='CALC ENGINE'!E23 | G26: ='CALC ENGINE'!T23 | H26: =IFERROR(SUMPRODUCT(($A$201:$A$293='MY PROFILE'!C10)*($B$201:$B$293=C26)*($C$201:$C$293)),0) | I26: =IF(G26=999,"",G26*2) | J26: =IF(G26=999,"",ROUND(G26*4/60,1)&" hrs") | K26: =IF(G26=999,"Unknown",IF('MY PROFILE'!G10="No Limit","Yes",IF('MY PROFILE'!G10="30 Minutes",IF(G26<=30,"Yes","No"),IF('MY PROFILE'!G10="1 Hour",IF(G26<=60,"Yes","No"),IF('MY PROFILE'!G10="1.5 Hours",IF(G26<=90,"Yes","No"),IF('MY PROFILE'!G10="2 Hours",IF(G26<=120,"Yes","No"),IF('MY PROFILE'!G10="3 Hours",IF(G26<=180,"Yes","No"),"No"))))))) | L26: =IF(G26=0,"Same City",IF(G26<=30,"Short",IF(G26<=90,"Medium",IF(G26<=180,"Long","Very Long")))) | M26: ='CALC ENGINE'!S23
B27: 22 | C27: ='CALC ENGINE'!B24 | D27: ='CALC ENGINE'!C24 | E27: ='CALC ENGINE'!D24 | F27: ='CALC ENGINE'!E24 | G27: ='CALC ENGINE'!T24 | H27: =IFERROR(SUMPRODUCT(($A$201:$A$293='MY PROFILE'!C10)*($B$201:$B$293=C27)*($C$201:$C$293)),0) | I27: =IF(G27=999,"",G27*2) | J27: =IF(G27=999,"",ROUND(G27*4/60,1)&" hrs") | K27: =IF(G27=999,"Unknown",IF('MY PROFILE'!G10="No Limit","Yes",IF('MY PROFILE'!G10="30 Minutes",IF(G27<=30,"Yes","No"),IF('MY PROFILE'!G10="1 Hour",IF(G27<=60,"Yes","No"),IF('MY PROFILE'!G10="1.5 Hours",IF(G27<=90,"Yes","No"),IF('MY PROFILE'!G10="2 Hours",IF(G27<=120,"Yes","No"),IF('MY PROFILE'!G10="3 Hours",IF(G27<=180,"Yes","No"),"No"))))))) | L27: =IF(G27=0,"Same City",IF(G27<=30,"Short",IF(G27<=90,"Medium",IF(G27<=180,"Long","Very Long")))) | M27: ='CALC ENGINE'!S24
B28: 23 | C28: ='CALC ENGINE'!B25 | D28: ='CALC ENGINE'!C25 | E28: ='CALC ENGINE'!D25 | F28: ='CALC ENGINE'!E25 | G28: ='CALC ENGINE'!T25 | H28: =IFERROR(SUMPRODUCT(($A$201:$A$293='MY PROFILE'!C10)*($B$201:$B$293=C28)*($C$201:$C$293)),0) | I28: =IF(G28=999,"",G28*2) | J28: =IF(G28=999,"",ROUND(G28*4/60,1)&" hrs") | K28: =IF(G28=999,"Unknown",IF('MY PROFILE'!G10="No Limit","Yes",IF('MY PROFILE'!G10="30 Minutes",IF(G28<=30,"Yes","No"),IF('MY PROFILE'!G10="1 Hour",IF(G28<=60,"Yes","No"),IF('MY PROFILE'!G10="1.5 Hours",IF(G28<=90,"Yes","No"),IF('MY PROFILE'!G10="2 Hours",IF(G28<=120,"Yes","No"),IF('MY PROFILE'!G10="3 Hours",IF(G28<=180,"Yes","No"),"No"))))))) | L28: =IF(G28=0,"Same City",IF(G28<=30,"Short",IF(G28<=90,"Medium",IF(G28<=180,"Long","Very Long")))) | M28: ='CALC ENGINE'!S25
B29: 24 | C29: ='CALC ENGINE'!B26 | D29: ='CALC ENGINE'!C26 | E29: ='CALC ENGINE'!D26 | F29: ='CALC ENGINE'!E26 | G29: ='CALC ENGINE'!T26 | H29: =IFERROR(SUMPRODUCT(($A$201:$A$293='MY PROFILE'!C10)*($B$201:$B$293=C29)*($C$201:$C$293)),0) | I29: =IF(G29=999,"",G29*2) | J29: =IF(G29=999,"",ROUND(G29*4/60,1)&" hrs") | K29: =IF(G29=999,"Unknown",IF('MY PROFILE'!G10="No Limit","Yes",IF('MY PROFILE'!G10="30 Minutes",IF(G29<=30,"Yes","No"),IF('MY PROFILE'!G10="1 Hour",IF(G29<=60,"Yes","No"),IF('MY PROFILE'!G10="1.5 Hours",IF(G29<=90,"Yes","No"),IF('MY PROFILE'!G10="2 Hours",IF(G29<=120,"Yes","No"),IF('MY PROFILE'!G10="3 Hours",IF(G29<=180,"Yes","No"),"No"))))))) | L29: =IF(G29=0,"Same City",IF(G29<=30,"Short",IF(G29<=90,"Medium",IF(G29<=180,"Long","Very Long")))) | M29: ='CALC ENGINE'!S26
B30: 25 | C30: ='CALC ENGINE'!B27 | D30: ='CALC ENGINE'!C27 | E30: ='CALC ENGINE'!D27 | F30: ='CALC ENGINE'!E27 | G30: ='CALC ENGINE'!T27 | H30: =IFERROR(SUMPRODUCT(($A$201:$A$293='MY PROFILE'!C10)*($B$201:$B$293=C30)*($C$201:$C$293)),0) | I30: =IF(G30=999,"",G30*2) | J30: =IF(G30=999,"",ROUND(G30*4/60,1)&" hrs") | K30: =IF(G30=999,"Unknown",IF('MY PROFILE'!G10="No Limit","Yes",IF('MY PROFILE'!G10="30 Minutes",IF(G30<=30,"Yes","No"),IF('MY PROFILE'!G10="1 Hour",IF(G30<=60,"Yes","No"),IF('MY PROFILE'!G10="1.5 Hours",IF(G30<=90,"Yes","No"),IF('MY PROFILE'!G10="2 Hours",IF(G30<=120,"Yes","No"),IF('MY PROFILE'!G10="3 Hours",IF(G30<=180,"Yes","No"),"No"))))))) | L30: =IF(G30=0,"Same City",IF(G30<=30,"Short",IF(G30<=90,"Medium",IF(G30<=180,"Long","Very Long")))) | M30: ='CALC ENGINE'!S27
B31: 26 | C31: ='CALC ENGINE'!B28 | D31: ='CALC ENGINE'!C28 | E31: ='CALC ENGINE'!D28 | F31: ='CALC ENGINE'!E28 | G31: ='CALC ENGINE'!T28 | H31: =IFERROR(SUMPRODUCT(($A$201:$A$293='MY PROFILE'!C10)*($B$201:$B$293=C31)*($C$201:$C$293)),0) | I31: =IF(G31=999,"",G31*2) | J31: =IF(G31=999,"",ROUND(G31*4/60,1)&" hrs") | K31: =IF(G31=999,"Unknown",IF('MY PROFILE'!G10="No Limit","Yes",IF('MY PROFILE'!G10="30 Minutes",IF(G31<=30,"Yes","No"),IF('MY PROFILE'!G10="1 Hour",IF(G31<=60,"Yes","No"),IF('MY PROFILE'!G10="1.5 Hours",IF(G31<=90,"Yes","No"),IF('MY PROFILE'!G10="2 Hours",IF(G31<=120,"Yes","No"),IF('MY PROFILE'!G10="3 Hours",IF(G31<=180,"Yes","No"),"No"))))))) | L31: =IF(G31=0,"Same City",IF(G31<=30,"Short",IF(G31<=90,"Medium",IF(G31<=180,"Long","Very Long")))) | M31: ='CALC ENGINE'!S28
B32: 27 | C32: ='CALC ENGINE'!B29 | D32: ='CALC ENGINE'!C29 | E32: ='CALC ENGINE'!D29 | F32: ='CALC ENGINE'!E29 | G32: ='CALC ENGINE'!T29 | H32: =IFERROR(SUMPRODUCT(($A$201:$A$293='MY PROFILE'!C10)*($B$201:$B$293=C32)*($C$201:$C$293)),0) | I32: =IF(G32=999,"",G32*2) | J32: =IF(G32=999,"",ROUND(G32*4/60,1)&" hrs") | K32: =IF(G32=999,"Unknown",IF('MY PROFILE'!G10="No Limit","Yes",IF('MY PROFILE'!G10="30 Minutes",IF(G32<=30,"Yes","No"),IF('MY PROFILE'!G10="1 Hour",IF(G32<=60,"Yes","No"),IF('MY PROFILE'!G10="1.5 Hours",IF(G32<=90,"Yes","No"),IF('MY PROFILE'!G10="2 Hours",IF(G32<=120,"Yes","No"),IF('MY PROFILE'!G10="3 Hours",IF(G32<=180,"Yes","No"),"No"))))))) | L32: =IF(G32=0,"Same City",IF(G32<=30,"Short",IF(G32<=90,"Medium",IF(G32<=180,"Long","Very Long")))) | M32: ='CALC ENGINE'!S29
B33: 28 | C33: ='CALC ENGINE'!B30 | D33: ='CALC ENGINE'!C30 | E33: ='CALC ENGINE'!D30 | F33: ='CALC ENGINE'!E30 | G33: ='CALC ENGINE'!T30 | H33: =IFERROR(SUMPRODUCT(($A$201:$A$293='MY PROFILE'!C10)*($B$201:$B$293=C33)*($C$201:$C$293)),0) | I33: =IF(G33=999,"",G33*2) | J33: =IF(G33=999,"",ROUND(G33*4/60,1)&" hrs") | K33: =IF(G33=999,"Unknown",IF('MY PROFILE'!G10="No Limit","Yes",IF('MY PROFILE'!G10="30 Minutes",IF(G33<=30,"Yes","No"),IF('MY PROFILE'!G10="1 Hour",IF(G33<=60,"Yes","No"),IF('MY PROFILE'!G10="1.5 Hours",IF(G33<=90,"Yes","No"),IF('MY PROFILE'!G10="2 Hours",IF(G33<=120,"Yes","No"),IF('MY PROFILE'!G10="3 Hours",IF(G33<=180,"Yes","No"),"No"))))))) | L33: =IF(G33=0,"Same City",IF(G33<=30,"Short",IF(G33<=90,"Medium",IF(G33<=180,"Long","Very Long")))) | M33: ='CALC ENGINE'!S30
B34: 29 | C34: ='CALC ENGINE'!B31 | D34: ='CALC ENGINE'!C31 | E34: ='CALC ENGINE'!D31 | F34: ='CALC ENGINE'!E31 | G34: ='CALC ENGINE'!T31 | H34: =IFERROR(SUMPRODUCT(($A$201:$A$293='MY PROFILE'!C10)*($B$201:$B$293=C34)*($C$201:$C$293)),0) | I34: =IF(G34=999,"",G34*2) | J34: =IF(G34=999,"",ROUND(G34*4/60,1)&" hrs") | K34: =IF(G34=999,"Unknown",IF('MY PROFILE'!G10="No Limit","Yes",IF('MY PROFILE'!G10="30 Minutes",IF(G34<=30,"Yes","No"),IF('MY PROFILE'!G10="1 Hour",IF(G34<=60,"Yes","No"),IF('MY PROFILE'!G10="1.5 Hours",IF(G34<=90,"Yes","No"),IF('MY PROFILE'!G10="2 Hours",IF(G34<=120,"Yes","No"),IF('MY PROFILE'!G10="3 Hours",IF(G34<=180,"Yes","No"),"No"))))))) | L34: =IF(G34=0,"Same City",IF(G34<=30,"Short",IF(G34<=90,"Medium",IF(G34<=180,"Long","Very Long")))) | M34: ='CALC ENGINE'!S31
B35: 30 | C35: ='CALC ENGINE'!B32 | D35: ='CALC ENGINE'!C32 | E35: ='CALC ENGINE'!D32 | F35: ='CALC ENGINE'!E32 | G35: ='CALC ENGINE'!T32 | H35: =IFERROR(SUMPRODUCT(($A$201:$A$293='MY PROFILE'!C10)*($B$201:$B$293=C35)*($C$201:$C$293)),0) | I35: =IF(G35=999,"",G35*2) | J35: =IF(G35=999,"",ROUND(G35*4/60,1)&" hrs") | K35: =IF(G35=999,"Unknown",IF('MY PROFILE'!G10="No Limit","Yes",IF('MY PROFILE'!G10="30 Minutes",IF(G35<=30,"Yes","No"),IF('MY PROFILE'!G10="1 Hour",IF(G35<=60,"Yes","No"),IF('MY PROFILE'!G10="1.5 Hours",IF(G35<=90,"Yes","No"),IF('MY PROFILE'!G10="2 Hours",IF(G35<=120,"Yes","No"),IF('MY PROFILE'!G10="3 Hours",IF(G35<=180,"Yes","No"),"No"))))))) | L35: =IF(G35=0,"Same City",IF(G35<=30,"Short",IF(G35<=90,"Medium",IF(G35<=180,"Long","Very Long")))) | M35: ='CALC ENGINE'!S32
B36: 31 | C36: ='CALC ENGINE'!B33 | D36: ='CALC ENGINE'!C33 | E36: ='CALC ENGINE'!D33 | F36: ='CALC ENGINE'!E33 | G36: ='CALC ENGINE'!T33 | H36: =IFERROR(SUMPRODUCT(($A$201:$A$293='MY PROFILE'!C10)*($B$201:$B$293=C36)*($C$201:$C$293)),0) | I36: =IF(G36=999,"",G36*2) | J36: =IF(G36=999,"",ROUND(G36*4/60,1)&" hrs") | K36: =IF(G36=999,"Unknown",IF('MY PROFILE'!G10="No Limit","Yes",IF('MY PROFILE'!G10="30 Minutes",IF(G36<=30,"Yes","No"),IF('MY PROFILE'!G10="1 Hour",IF(G36<=60,"Yes","No"),IF('MY PROFILE'!G10="1.5 Hours",IF(G36<=90,"Yes","No"),IF('MY PROFILE'!G10="2 Hours",IF(G36<=120,"Yes","No"),IF('MY PROFILE'!G10="3 Hours",IF(G36<=180,"Yes","No"),"No"))))))) | L36: =IF(G36=0,"Same City",IF(G36<=30,"Short",IF(G36<=90,"Medium",IF(G36<=180,"Long","Very Long")))) | M36: ='CALC ENGINE'!S33
B37: 32 | C37: ='CALC ENGINE'!B34 | D37: ='CALC ENGINE'!C34 | E37: ='CALC ENGINE'!D34 | F37: ='CALC ENGINE'!E34 | G37: ='CALC ENGINE'!T34 | H37: =IFERROR(SUMPRODUCT(($A$201:$A$293='MY PROFILE'!C10)*($B$201:$B$293=C37)*($C$201:$C$293)),0) | I37: =IF(G37=999,"",G37*2) | J37: =IF(G37=999,"",ROUND(G37*4/60,1)&" hrs") | K37: =IF(G37=999,"Unknown",IF('MY PROFILE'!G10="No Limit","Yes",IF('MY PROFILE'!G10="30 Minutes",IF(G37<=30,"Yes","No"),IF('MY PROFILE'!G10="1 Hour",IF(G37<=60,"Yes","No"),IF('MY PROFILE'!G10="1.5 Hours",IF(G37<=90,"Yes","No"),IF('MY PROFILE'!G10="2 Hours",IF(G37<=120,"Yes","No"),IF('MY PROFILE'!G10="3 Hours",IF(G37<=180,"Yes","No"),"No"))))))) | L37: =IF(G37=0,"Same City",IF(G37<=30,"Short",IF(G37<=90,"Medium",IF(G37<=180,"Long","Very Long")))) | M37: ='CALC ENGINE'!S34
B38: 33 | C38: ='CALC ENGINE'!B35 | D38: ='CALC ENGINE'!C35 | E38: ='CALC ENGINE'!D35 | F38: ='CALC ENGINE'!E35 | G38: ='CALC ENGINE'!T35 | H38: =IFERROR(SUMPRODUCT(($A$201:$A$293='MY PROFILE'!C10)*($B$201:$B$293=C38)*($C$201:$C$293)),0) | I38: =IF(G38=999,"",G38*2) | J38: =IF(G38=999,"",ROUND(G38*4/60,1)&" hrs") | K38: =IF(G38=999,"Unknown",IF('MY PROFILE'!G10="No Limit","Yes",IF('MY PROFILE'!G10="30 Minutes",IF(G38<=30,"Yes","No"),IF('MY PROFILE'!G10="1 Hour",IF(G38<=60,"Yes","No"),IF('MY PROFILE'!G10="1.5 Hours",IF(G38<=90,"Yes","No"),IF('MY PROFILE'!G10="2 Hours",IF(G38<=120,"Yes","No"),IF('MY PROFILE'!G10="3 Hours",IF(G38<=180,"Yes","No"),"No"))))))) | L38: =IF(G38=0,"Same City",IF(G38<=30,"Short",IF(G38<=90,"Medium",IF(G38<=180,"Long","Very Long")))) | M38: ='CALC ENGINE'!S35
B39: 34 | C39: ='CALC ENGINE'!B36 | D39: ='CALC ENGINE'!C36 | E39: ='CALC ENGINE'!D36 | F39: ='CALC ENGINE'!E36 | G39: ='CALC ENGINE'!T36 | H39: =IFERROR(SUMPRODUCT(($A$201:$A$293='MY PROFILE'!C10)*($B$201:$B$293=C39)*($C$201:$C$293)),0) | I39: =IF(G39=999,"",G39*2) | J39: =IF(G39=999,"",ROUND(G39*4/60,1)&" hrs") | K39: =IF(G39=999,"Unknown",IF('MY PROFILE'!G10="No Limit","Yes",IF('MY PROFILE'!G10="30 Minutes",IF(G39<=30,"Yes","No"),IF('MY PROFILE'!G10="1 Hour",IF(G39<=60,"Yes","No"),IF('MY PROFILE'!G10="1.5 Hours",IF(G39<=90,"Yes","No"),IF('MY PROFILE'!G10="2 Hours",IF(G39<=120,"Yes","No"),IF('MY PROFILE'!G10="3 Hours",IF(G39<=180,"Yes","No"),"No"))))))) | L39: =IF(G39=0,"Same City",IF(G39<=30,"Short",IF(G39<=90,"Medium",IF(G39<=180,"Long","Very Long")))) | M39: ='CALC ENGINE'!S36
B40: 35 | C40: ='CALC ENGINE'!B37 | D40: ='CALC ENGINE'!C37 | E40: ='CALC ENGINE'!D37 | F40: ='CALC ENGINE'!E37 | G40: ='CALC ENGINE'!T37 | H40: =IFERROR(SUMPRODUCT(($A$201:$A$293='MY PROFILE'!C10)*($B$201:$B$293=C40)*($C$201:$C$293)),0) | I40: =IF(G40=999,"",G40*2) | J40: =IF(G40=999,"",ROUND(G40*4/60,1)&" hrs") | K40: =IF(G40=999,"Unknown",IF('MY PROFILE'!G10="No Limit","Yes",IF('MY PROFILE'!G10="30 Minutes",IF(G40<=30,"Yes","No"),IF('MY PROFILE'!G10="1 Hour",IF(G40<=60,"Yes","No"),IF('MY PROFILE'!G10="1.5 Hours",IF(G40<=90,"Yes","No"),IF('MY PROFILE'!G10="2 Hours",IF(G40<=120,"Yes","No"),IF('MY PROFILE'!G10="3 Hours",IF(G40<=180,"Yes","No"),"No"))))))) | L40: =IF(G40=0,"Same City",IF(G40<=30,"Short",IF(G40<=90,"Medium",IF(G40<=180,"Long","Very Long")))) | M40: ='CALC ENGINE'!S37
B41: 36 | C41: ='CALC ENGINE'!B38 | D41: ='CALC ENGINE'!C38 | E41: ='CALC ENGINE'!D38 | F41: ='CALC ENGINE'!E38 | G41: ='CALC ENGINE'!T38 | H41: =IFERROR(SUMPRODUCT(($A$201:$A$293='MY PROFILE'!C10)*($B$201:$B$293=C41)*($C$201:$C$293)),0) | I41: =IF(G41=999,"",G41*2) | J41: =IF(G41=999,"",ROUND(G41*4/60,1)&" hrs") | K41: =IF(G41=999,"Unknown",IF('MY PROFILE'!G10="No Limit","Yes",IF('MY PROFILE'!G10="30 Minutes",IF(G41<=30,"Yes","No"),IF('MY PROFILE'!G10="1 Hour",IF(G41<=60,"Yes","No"),IF('MY PROFILE'!G10="1.5 Hours",IF(G41<=90,"Yes","No"),IF('MY PROFILE'!G10="2 Hours",IF(G41<=120,"Yes","No"),IF('MY PROFILE'!G10="3 Hours",IF(G41<=180,"Yes","No"),"No"))))))) | L41: =IF(G41=0,"Same City",IF(G41<=30,"Short",IF(G41<=90,"Medium",IF(G41<=180,"Long","Very Long")))) | M41: ='CALC ENGINE'!S38
...

Sheet CAREER TIMELINE
B1: CAREER TIMELINE | Suggested 10–20 Year Pathway Based on Your Profile
B2: ="Rank: "&'MY PROFILE'!C6&" | MOS: "&'MY PROFILE'!C7&" | Goal: "&'MY PROFILE'!C25&" | Primary Goal: "&'MY PROFILE'!C26
B3: This timeline is a PLANNING GUIDE, not a guarantee. Adjust based on force structure, available positions, and board outcomes. Positions typically held 2–3 years each.
B5: ENLISTED CAREER PATH — Example: 92Y → SFC → MSG (Goal)
C6: E5 / SGT Team Leader / Supply SGT (2–3 yrs) BLC → ALC Prep | D6: ALC Advanced Leader Course (3 wks yrs) Fort Lee or Regional | E6: E6 / SSG Section NCOIC / SL (2–3 yrs) KD: Lead soldiers | F6: SLC Senior Leader Course (6 wks yrs) USASMA competitive | G6: E7 / SFC Platoon SGT / Staff (2–3 yrs) Broaden experience | H6: E8 / MSG 1SG or Senior Staff (3+ yrs) Senior leader track | I6: E8 1SG Company 1SG (2–3 yrs) Pinnacle for many
C9: ─────────────────────────────────────────────────────────────────────→ | D9: ─────────────────────────────────────────────────────────────────────→ | E9: ─────────────────────────────────────────────────────────────────────→ | F9: ─────────────────────────────────────────────────────────────────────→ | G9: ─────────────────────────────────────────────────────────────────────→ | H9: ─────────────────────────────────────────────────────────────────────→ | I9: ─────────────────────────────────────────────────────────────────────→
B11: OFFICER CAREER PATH — Example: 2LT → CPT (Company Command) → MAJ → LTC
C12: O1-O2 Platoon Leader / XO (2–3 yrs) BOLC → branch qual | D12: CCC Captain's Career Course (4 mos yrs) Branch school | E12: O3 CPT Company Command (2 yrs) KD: Pinnacle CPT | F12: O3 CPT Battalion Staff S3/S4/S1 (2 yrs) KD staff tour | G12: ILE Intermediate Level Ed (1 yr yrs) CGSC / non-res | H12: O5 LTC Battalion Command (2 yrs) BN CDR — elite | I12: O5 LTC Brigade Staff / J-Staff (3+ yrs) Senior staff
B17: WARRANT OFFICER PATH — Example: WO1 → CW3 → CW5 (Senior Warrant)
C18: WOFT / WOBC Warrant Officer Basic Course (6–18 mo yrs) IERW if aviator | D18: CW2 Tech Expert in MOS (3–4 yrs) WOAC prep | E18: WOAC Warrant Officer Advanced Course (3 wks yrs) MOS branch school | F18: CW3 Senior Tech Advisor (3–4 yrs) WOILE prep | G18: WOILE / WOSSE WO Intermediate Level Ed (3 wks yrs) Fort Leavenworth | H18: CW4 Senior Warrant Leader (4+ yrs) Mentor CW1/CW2 | I18: CW5 Chief Warrant Officer 5 (3+ yrs) Rare — senior WO
B23: KEY DECISION GATES — When to take action
B24: E4→E5 | C24: Enroll in BLC. Ensure SSD1 complete. Ask unit for recommendation letter.
B25: E5→E6 | C25: Complete ALC. Serve in leadership position. Build OER/NCOER support file.
B26: E6→E7 (SFC) | C26: Compete for SLC. Seek platoon sergeant or staff NCOIC. Consider AGR track.
B27: E7→E8 (MSG) | C27: SLC complete. Centralized board. 1SG assignment is key. Build senior rater relationship.
B28: Command Track | C28: Pre-Command Course required. Build relationship with BN CDR and retention NCO.
B29: WO Interest | C29: Talk to state WO recruiter. SIFT test. Class 1A physical (if aviation). Strong GT score.
B30: AGR Interest | C30: Contact state AGR office. Position must be vacant. AGR tour = active duty benefits.
B31: MOS Switch | C31: Talk to retention NCO. Check line scores and waivers. Plan MOSQ school time off work.
B33: TIMELINE LEGEND
B34: School/PME
B35: Leadership
B36: Staff
B37: Command
B38: Broadening
B39: Transition

Sheet COUNSELING SHEET
B1: MONTANA ARMY NATIONAL GUARD — SOLDIER CAREER COUNSELING SHEET
B2: ="As of: "&TEXT(TODAY(),"MMMM DD, YYYY")&" | Prepared for: "&'MY PROFILE'!C6&" "&'MY PROFILE'!C5&" | MOS: "&'MY PROFILE'!C7&" | Home: "&'MY PROFILE'!C10
B3: SECTION 1 — CURRENT SNAPSHOT
B4: Rank / Grade | C4: ='MY PROFILE'!C6 | F4: Career Category | G4: ='MY PROFILE'!E6
B5: MOS / AOC | C5: ='MY PROFILE'!C7 | F5: Component | G5: ='MY PROFILE'!G6
B6: Unit | C6: ='MY PROFILE'!C8 | F6: Unit City | G6: ='MY PROFILE'!G9
B7: Current Title | C7: ='MY PROFILE'!C9 | F7: Years of Service | G7: ='MY PROFILE'!C11
B8: TIG (yrs) | C8: ='MY PROFILE'!E11 | F8: TIS / Svc Entry | G8: ='MY PROFILE'!E12
B9: Clearance | C9: ='MY PROFILE'!E42 | F9: APFT Status | G9: ='MY PROFILE'!C42
B10: SECTION 2 — PME STATUS
B11: BLC | C11: ALC | D11: SLC | E11: SMC | F11: BOLC | G11: CCC | H11: ILE | I11: SSC | J11: WOBC | K11: WOAC
B12: ='MY PROFILE'!C16 | C12: ='MY PROFILE'!C17 | D12: ='MY PROFILE'!C18 | E12: ='MY PROFILE'!C19 | F12: ='MY PROFILE'!C16 | G12: ='MY PROFILE'!C17 | H12: ='MY PROFILE'!C18 | I12: ='MY PROFILE'!C19 | J12: ='MY PROFILE'!G16 | K12: ='MY PROFILE'!G17
B13: SECTION 3 — CAREER GOALS
B14: Target Rank | C14: ='MY PROFILE'!C25 | F14: Primary Goal | G14: ='MY PROFILE'!C26
B15: Goal Timeline | C15: ='MY PROFILE'!E25 | F15: Preferred Status | G15: ='MY PROFILE'!G25
B16: Position Type | C16: ='MY PROFILE'!C27 | F16: Open to Command? | G16: ='MY PROFILE'!E27
B17: Switch MOS? | C17: ='MY PROFILE'!G27 | F17: WO Interest? | G17: ='MY PROFILE'!E28
B18: Willing to Relocate? | C18: ='MY PROFILE'!G12 | F18: Max Commute | G18: ='MY PROFILE'!G10
B19: 5-Year Goal Statement | C19: ='MY PROFILE'!B31
B21: SECTION 4 — TOP POSITION MATCHES (from POSITION MATCHES sheet)
B22: Rank | C22: Unit | D22: City | E22: Duty Title | F22: Duty Title | I22: Match | J22: Commute
B23: ='POSITION MATCHES'!C6 | C23: ='POSITION MATCHES'!D6 | E23: ='POSITION MATCHES'!F6 | F23: ='POSITION MATCHES'!E6 | I23: ='POSITION MATCHES'!K6 | J23: ='POSITION MATCHES'!R6 | K23: ='POSITION MATCHES'!S6
B24: ='POSITION MATCHES'!C7 | C24: ='POSITION MATCHES'!D7 | E24: ='POSITION MATCHES'!F7 | F24: ='POSITION MATCHES'!E7 | I24: ='POSITION MATCHES'!K7 | J24: ='POSITION MATCHES'!R7 | K24: ='POSITION MATCHES'!S7
B25: ='POSITION MATCHES'!C8 | C25: ='POSITION MATCHES'!D8 | E25: ='POSITION MATCHES'!F8 | F25: ='POSITION MATCHES'!E8 | I25: ='POSITION MATCHES'!K8 | J25: ='POSITION MATCHES'!R8 | K25: ='POSITION MATCHES'!S8
B26: ='POSITION MATCHES'!C9 | C26: ='POSITION MATCHES'!D9 | E26: ='POSITION MATCHES'!F9 | F26: ='POSITION MATCHES'!E9 | I26: ='POSITION MATCHES'!K9 | J26: ='POSITION MATCHES'!R9 | K26: ='POSITION MATCHES'!S9
B27: ='POSITION MATCHES'!C10 | C27: ='POSITION MATCHES'!D10 | E27: ='POSITION MATCHES'!F10 | F27: ='POSITION MATCHES'!E10 | I27: ='POSITION MATCHES'!K10 | J27: ='POSITION MATCHES'!R10 | K27: ='POSITION MATCHES'!S10
B29: SECTION 5 — GAPS TO CLOSE (Complete before next board/assignment)
B30: PME Required | C30: ='MY PROFILE'!C17 | F30: Status | G30: ='MY PROFILE'!C17
B31: Schools Recommended | C31: SLC — see PME sheet | F31: Timeline | G31: Within 2 years
B32: MOS Qualification | C32: N/A — current MOS qualified | F32: Action | G32: Maintain currency
B33: Deployment / OCONUS | C33: ='MY PROFILE'!G42 | F33: Impact | G33: Points toward senior boards
B34: Education Goal | C34: ='MY PROFILE'!C22 | F34: Gap | G34: Complete bachelor's degree
B36: SECTION 6 — SUGGESTED NEAR-TERM CAREER PATHWAY
B37: NOW (0–2 yrs) | C37: Complete ALC. Stay in current position. Build NCOER support file. Target E6 board.
B38: MID (2–5 yrs) | C38: Move to Squad Leader / NCOIC role. Attend SLC. Consider AGR conversion opportunity.
B39: GOAL (5–10 yrs) | C39: Compete for SFC. Seek platoon sergeant billet. Position near Helena or AGR statewide.
B40: SECTION 7 — DISCUSSION POINTS FOR THIS COUNSELING SESSION
B41: 1. Next promotion board — Is the Soldier on track? What does the senior rater need to see?
B42: 2. Position of Interest — Are the matched positions realistic? Is command/KD needed?
B43: 3. AGR opportunity — Is the Soldier interested? Any open AGR billets to discuss?
...

Sheet ADMIN - POSITIONS
A1: ⚠ ADMIN SHEET — POSITION REFERENCE DATABASE | Replace [DEMO] rows with real MTARNG UMR/MTOE data
A2: Row ID | B2: Unit Name | C2: UIC | D2: City / Location | E2: Duty Title | F2: Grade | G2: Career Category | H2: MOS / AOC | I2: Branch / FA | J2: Position Type | K2: Command or KD | L2: Status Type | M2: Vacancy Status | N2: Proj Vacancy Date | O2: Secondary MOS OK | P2: Match Weight Override | Q2: Notes | R2: DEMO FLAG
A3: 1 | B3: 1-189th IN BN, A Co | C3: W4MMB3 | D3: Billings | E3: Rifle Team Leader | F3: E5 | G3: Enlisted | H3: 11B | I3: IN | J3: Leadership | K3: No | L3: M-Day | M3: Filled | Q3: Squad/team ldr pos | R3: [DEMO]
A4: 2 | B4: 1-189th IN BN, A Co | C4: W4MMB3 | D4: Billings | E4: Squad Leader | F4: E6 | G4: Enlisted | H4: 11B | I4: IN | J4: Leadership | K4: Yes | L4: M-Day | M4: Vacant | N4: 2026-09-01 | Q4: KD for promotable SSG | R4: [DEMO]
A5: 3 | B5: 1-189th IN BN, HHC | C5: W4MMB4 | D5: Billings | E5: Operations SGT | F5: E7 | G5: Enlisted | H5: 11B | I5: IN | J5: Staff | K5: No | L5: M-Day | M5: Filled | Q5: Batt ops shop | R5: [DEMO]
A6: 4 | B6: 1-189th IN BN, HHC | C6: W4MMB4 | D6: Billings | E6: Readiness NCO | F6: E7 | G6: Enlisted | H6: 92Y | I6: AG | J6: Staff | K6: No | L6: AGR | M6: Filled | Q6: Full-time readiness | R6: [DEMO]
A7: 5 | B7: 1-189th IN BN, HHC | C7: W4MMB4 | D7: Billings | E7: S4 NCOIC | F7: E7 | G7: Enlisted | H7: 92Y | I7: LG | J7: Staff | K7: No | L7: M-Day | M7: Vacant | Q7: Log/supply focus | R7: [DEMO]
A8: 6 | B8: 1-189th IN BN, HHC | C8: W4MMB4 | D8: Billings | E8: 1SG, A Co | F8: E8 | G8: Enlisted | H8: 11B | I8: IN | J8: Command | K8: Yes | L8: M-Day | M8: Filled | Q8: Senior Enlisted Leader | R8: [DEMO]
A9: 7 | B9: 1-189th IN BN | C9: W4MMB4 | D9: Billings | E9: CSM, 1-189th IN BN | F9: E9 | G9: Enlisted | H9: 11B | I9: IN | J9: Command | K9: Yes | L9: M-Day | M9: Filled | N9: 2027-06-01 | Q9: BN CSM | R9: [DEMO]
A10: 8 | B10: 1-189th IN BN | C10: W4MMB4 | D10: Billings | E10: S3, 1-189th IN BN | F10: O3 | G10: Officer | H10: 11A | I10: IN | J10: Staff | K10: Yes | L10: M-Day | M10: Filled | Q10: KD staff tour | R10: [DEMO]
A11: 9 | B11: 1-189th IN BN | C11: W4MMB4 | D11: Billings | E11: CDR, A Co, 1-189th IN BN | F11: O3 | G11: Officer | H11: 11A | I11: IN | J11: Command | K11: Yes | L11: M-Day | M11: Vacant | N11: 2026-07-01 | Q11: Company command window | R11: [DEMO]
A12: 10 | B12: 1-189th IN BN | C12: W4MMB4 | D12: Billings | E12: XO, 1-189th IN BN | F12: O4 | G12: Officer | H12: 11A | I12: IN | J12: Staff | K12: Yes | L12: M-Day | M12: Filled | Q12: BN XO | R12: [DEMO]
A13: 11 | B13: 1-189th IN BN | C13: W4MMB4 | D13: Billings | E13: CDR, 1-189th IN BN | F13: O5 | G13: Officer | H13: 11A | I13: IN | J13: Command | K13: Yes | L13: M-Day | M13: Filled | N13: 2028-01-01 | Q13: BN Command | R13: [DEMO]
A14: 12 | B14: 163d Cavalry, HHT | C14: W4MM92 | D14: Billings | E14: Supply SGT | F14: E6 | G14: Enlisted | H14: 92Y | I14: LG | J14: Technical | K14: No | L14: M-Day | M14: Filled | Q14: Unit supply | R14: [DEMO]
A15: 13 | B15: 163d Cavalry, HHT | C15: W4MM92 | D15: Billings | E15: Property Book NCO | F15: E7 | G15: Enlisted | H15: 92Y | I15: LG | J15: Staff | K15: No | L15: AGR | M15: Vacant | N15: 2026-10-01 | Q15: AGR PB NCO | R15: [DEMO]
A16: 14 | B16: 163d Cavalry, HHT | C16: W4MM92 | D16: Billings | E16: Warrant Officer — Property | F16: W2 | G16: Warrant | H16: 920A | I16: LG | J16: Technical | K16: No | L16: M-Day | M16: Filled | Q16: Property Accounting Tech | R16: [DEMO]
A17: 15 | B17: 163d Cavalry, HHT | C17: W4MM92 | D17: Billings | E17: Troop CDR, HHT | F17: O3 | G17: Officer | H17: 19A | I17: AR | J17: Command | K17: Yes | L17: M-Day | M17: Filled | R17: [DEMO]
A18: 16 | B18: MTARNG G1 / USPFO | C18: W4M001 | D18: Helena | E18: Personnel SGT | F18: E5 | G18: Enlisted | H18: 42A | I18: AG | J18: Staff | K18: No | L18: AGR | M18: Filled | Q18: State HQ HR | R18: [DEMO]
A19: 17 | B19: MTARNG G1 / USPFO | C19: W4M001 | D19: Helena | E19: HR NCOIC | F19: E7 | G19: Enlisted | H19: 42A | I19: AG | J19: Staff | K19: No | L19: AGR | M19: Filled | R19: [DEMO]
A20: 18 | B20: MTARNG G3 | C20: W4M001 | D20: Helena | E20: Training NCO | F20: E7 | G20: Enlisted | H20: 11B | I20: IN | J20: Staff | K20: No | L20: AGR | M20: Vacant | N20: 2027-03-01 | Q20: State G3 shop | R20: [DEMO]
A21: 19 | B21: MTARNG G4 | C21: W4M001 | D21: Helena | E21: Logistics SGT | F21: E6 | G21: Enlisted | H21: 92A | I21: LG | J21: Staff | K21: No | L21: AGR | M21: Filled | Q21: State log shop | R21: [DEMO]
A22: 20 | B22: MTARNG G4 | C22: W4M001 | D22: Helena | E22: G4 NCOIC | F22: E8 | G22: Enlisted | H22: 92A | I22: LG | J22: Staff | K22: No | L22: AGR | M22: Filled | N22: 2027-06-01 | R22: [DEMO]
A23: 21 | B23: MTARNG HQ | C23: W4M001 | D23: Helena | E23: State Command Sergeant Major | F23: E9 | G23: Enlisted | H23: 00Z | I23: IN | J23: Command | K23: Yes | L23: AGR | M23: Filled | Q23: State CSM | R23: [DEMO]
A24: 22 | B24: MTARNG HQ | C24: W4M001 | D24: Helena | E24: G1, MTARNG | F24: O5 | G24: Officer | H24: 42H | I24: AG | J24: Staff | K24: Yes | L24: AGR | M24: Filled | R24: [DEMO]
A25: 23 | B25: MTARNG HQ | C25: W4M001 | D25: Helena | E25: G3, MTARNG | F25: O5 | G25: Officer | H25: 11A | I25: IN | J25: Staff | K25: Yes | L25: AGR | M25: Filled | N25: 2027-09-01 | R25: [DEMO]
A26: 24 | B26: MTARNG HQ | C26: W4M001 | D26: Helena | E26: The Adjutant General | F26: O8 | G26: Officer | H26: 00A | I26: IN | J26: Command | K26: Yes | L26: AGR | M26: Filled | Q26: TAG | R26: [DEMO]
A27: 25 | B27: 240th Engineer Co | C27: W4MMEC | D27: Helena | E27: Combat Engineer | F27: E4 | G27: Enlisted | H27: 12B | I27: EN | J27: Technical | K27: No | L27: M-Day | M27: Vacant | R27: [DEMO]
A28: 26 | B28: 240th Engineer Co | C28: W4MMEC | D28: Helena | E28: Equipment Operator | F28: E5 | G28: Enlisted | H28: 12B | I28: EN | J28: Technical | K28: No | L28: M-Day | M28: Filled | R28: [DEMO]
A29: 27 | B29: 240th Engineer Co | C29: W4MMEC | D29: Helena | E29: Squad Leader | F29: E6 | G29: Enlisted | H29: 12B | I29: EN | J29: Leadership | K29: Yes | L29: M-Day | M29: Vacant | N29: 2026-10-01 | R29: [DEMO]
A30: 28 | B30: 240th Engineer Co | C30: W4MMEC | D30: Helena | E30: Platoon Sergeant | F30: E7 | G30: Enlisted | H30: 12B | I30: EN | J30: Leadership | K30: Yes | L30: M-Day | M30: Filled | R30: [DEMO]
A31: 29 | B31: 240th Engineer Co | C31: W4MMEC | D31: Helena | E31: 1SG, 240th Eng Co | F31: E8 | G31: Enlisted | H31: 12B | I31: EN | J31: Command | K31: Yes | L31: M-Day | M31: Filled | N31: 2028-01-01 | R31: [DEMO]
A32: 30 | B32: 240th Engineer Co | C32: W4MMEC | D32: Helena | E32: CDR, 240th Engineer Co | F32: O3 | G32: Officer | H32: 12A | I32: EN | J32: Command | K32: Yes | L32: M-Day | M32: Vacant | N32: 2026-07-01 | Q32: Company command | R32: [DEMO]
A33: 31 | B33: 1-163d IN BN, B Co | C33: W4MMBF | D33: Great Falls | E33: Rifle Team Leader | F33: E5 | G33: Enlisted | H33: 11B | I33: IN | J33: Leadership | K33: No | L33: M-Day | M33: Filled | R33: [DEMO]
A34: 32 | B34: 1-163d IN BN, B Co | C34: W4MMBF | D34: Great Falls | E34: Squad Leader | F34: E6 | G34: Enlisted | H34: 11B | I34: IN | J34: Leadership | K34: Yes | L34: M-Day | M34: Filled | R34: [DEMO]
A35: 33 | B35: 1-163d IN BN, B Co | C35: W4MMBF | D35: Great Falls | E35: Weapons Squad Leader | F35: E6 | G35: Enlisted | H35: 11B | I35: IN | J35: Leadership | K35: Yes | L35: M-Day | M35: Vacant | N35: 2026-09-01 | Q35: Weapons platoon | R35: [DEMO]
A36: 34 | B36: 1-163d IN BN, HHC | C36: W4MMBG | D36: Great Falls | E36: Comms SGT | F36: E6 | G36: Enlisted | H36: 25U | I36: SC | J36: Technical | K36: No | L36: M-Day | M36: Vacant | R36: [DEMO]
A37: 35 | B37: 1-163d IN BN, HHC | C37: W4MMBG | D37: Great Falls | E37: S6 NCOIC | F37: E7 | G37: Enlisted | H37: 25U | I37: SC | J37: Staff | K37: No | L37: M-Day | M37: Filled | R37: [DEMO]
A38: 36 | B38: 1-163d IN BN, HHC | C38: W4MMBG | D38: Great Falls | E38: Network Tech WO | F38: W2 | G38: Warrant | H38: 255A | I38: SC | J38: Technical | K38: No | L38: M-Day | M38: Filled | R38: [DEMO]
A39: 37 | B39: 1-163d IN BN, HHC | C39: W4MMBG | D39: Great Falls | E39: Intel Officer | F39: O2 | G39: Officer | H39: 35D | I39: MI | J39: Staff | K39: No | L39: M-Day | M39: Vacant | Q39: HUMINT/GEOINT | R39: [DEMO]
A40: 38 | B40: 1-163d IN BN, HHC | C40: W4MMBG | D40: Great Falls | E40: S2, 1-163d IN BN | F40: O3 | G40: Officer | H40: 35D | I40: MI | J40: Staff | K40: Yes | L40: M-Day | M40: Filled | R40: [DEMO]
...

Sheet ADMIN - CITY DISTANCES
A1: ⚠ ADMIN SHEET — MONTANA CITY DRIVE TIME & DISTANCE MATRIX | Verify against Google Maps / OSRM before operational use
A2: From City | B2: To City | C2: Miles (One Way) | D2: Drive Time (hrs:min) | E2: Route Notes | F2: DEMO FLAG
A3: Billings | B3: Bozeman | C3: 144 | D3: 2:10 | E3: I-90 W | F3: [DEMO]
A4: Billings | B4: Butte | C4: 223 | D4: 3:10 | E4: I-90 W | F4: [DEMO]
A5: Billings | B5: Helena | C5: 221 | D5: 3:05 | E5: I-90 W / US-12 W | F5: [DEMO]
A6: Billings | B6: Great Falls | C6: 225 | D6: 3:15 | E6: US-87 N | F6: [DEMO]
A7: Billings | B7: Missoula | C7: 344 | D7: 4:45 | E7: I-90 W | F7: [DEMO]
A8: Billings | B8: Kalispell | C8: 449 | D8: 6:10 | E8: I-90 W / US-93 N | F8: [DEMO]
A9: Billings | B9: Miles City | C9: 141 | D9: 2:05 | E9: I-94 E | F9: [DEMO]
A10: Billings | B10: Dillon | C10: 302 | D10: 4:15 | E10: I-90 W / I-15 S | F10: [DEMO]
A11: Billings | B11: Havre | C11: 231 | D11: 3:20 | E11: US-87 N | F11: [DEMO]
A12: Billings | B12: Lewistown | C12: 126 | D12: 1:55 | E12: US-87 N | F12: [DEMO]
A13: Billings | B13: Livingston | C13: 115 | D13: 1:40 | E13: I-90 W | F13: [DEMO]
A14: Billings | B14: Glendive | C14: 213 | D14: 3:00 | E14: I-94 E | F14: [DEMO]
... A44: Great Falls | B44: Glasgow | C44: 228 | D44: 3:10 | E44: US-2 E | F44: [DEMO]

Sheet ADMIN - PME AND SCHOOLS
A1: ⚠ ADMIN SHEET — PME & SCHOOL REQUIREMENTS | Update as AR 350-1 / ARNG policy changes
A2: Career Cat | B2: Grade | C2: PME / Course | D2: Course Code | E2: Required or Recommended | F2: Prerequisite | G2: Duration | H2: Where Taught | I2: Notes | J2: DEMO FLAG
A3: Enlisted | B3: E4-E5 | C3: Basic Leader Course (BLC) | D3: BLC | E3: Required for E5 promotion | F3: SSD1 complete | G3: 3 weeks | H3: Regional NCO Academy | I3: Must complete before SPC-SGT promotion board | J3: [DEMO]
A4: Enlisted | B4: E5-E6 | C4: Advanced Leader Course (ALC) | D4: ALC | E4: Required for E6 promotion | F4: BLC complete | G4: 4 weeks | H4: Regional NCO Academy | I4: Selectee attendance within 1 year of board selection | J4: [DEMO]
A5: Enlisted | B5: E6-E7 | C5: Senior Leader Course (SLC) | D5: SLC | E5: Required for E7 promotion | F5: ALC complete | G5: 6 weeks | H5: Sergeant Major Academy (USASMA) | I5: Competitive attendance; centrally managed | J5: [DEMO]
A6: Enlisted | B6: E8-E9 | C6: Sergeant Major Course (SMC) | D6: SMC | E6: Required for CSM selection | F6: SLC complete | G6: 10 months | H6: USASMA Fort Bliss TX | I6: Highly competitive; CSM prerequisite | J6: [DEMO]
A7: Enlisted | B7: E5+ | C7: Structured Self Development 1 (SSD1) | D7: SSD1 | E7: Required for BLC attendance | F7: None | G7: Online | H7: AKO / Army e-Learning | I7: Complete prior to BLC registration | J7: [DEMO]
A8: Enlisted | B8: E5+ | C8: Structured Self Development 2 (SSD2) | D8: SSD2 | E8: Required for ALC attendance | F8: BLC + SSD1 | G8: Online | H8: AKO / Army e-Learning | J8: [DEMO]
